<mujoco>
  <compiler meshdir="../assets/urdf/meshes/" angle="radian" />

  <asset>
    <mesh name="base_link" content_type="model/stl" file="base_link.stl" />
    <mesh name="link_1" content_type="model/stl" file="link_1.stl" />
    <mesh name="link_2" content_type="model/stl" file="link_2.stl" />
    <mesh name="link_3" content_type="model/stl" file="link_3.stl" />
    <mesh name="link_4" content_type="model/stl" file="link_4.stl" />
    <mesh name="link_5" content_type="model/stl" file="link_5.stl" />
    <mesh name="link_6" content_type="model/stl" file="link_6.stl" />
  </asset>

  <worldbody>
    
    <body name="kuka_base" pos="0 -0.3 0.85">

      

      
      <geom type="mesh" rgba="0.3 0.3 0.3 1" mesh="base_link" contype="0" conaffinity="0" />

      
      <body name="link_1" pos="0 0 0.4">
        <joint name="joint_a1" pos="0 0 0" axis="0 0 -1" range="-2.96706 2.96706" limited="true" />
        <geom type="mesh" rgba="1 0.42 0 1" mesh="link_1" contype="1" conaffinity="2" />

        <body name="link_2" pos="0.025 0 0">
          <joint name="joint_a2" pos="0 0 0" axis="0 1 0" range="-3.31613 0.785398" limited="true" />
          <geom type="mesh" rgba="1 0.42 0 1" mesh="link_2" contype="1" conaffinity="2" />

          <body name="link_3" pos="0.455 0 0">
            <joint name="joint_a3" pos="0 0 0" axis="0 1 0" range="-2.0944 2.72271" limited="true" />
            <geom type="mesh" rgba="1 0.42 0 1" mesh="link_3" contype="1" conaffinity="2" />

            <body name="link_4" pos="0 0 0.035">
              <joint name="joint_a4" pos="0 0 0" axis="-1 0 0" range="-3.22886 3.22886" limited="true" />
              <geom type="mesh" rgba="1 0.42 0 1" mesh="link_4" contype="1" conaffinity="2" />

              <body name="link_5" pos="0.42 0 0">
                <joint name="joint_a5" pos="0 0 0" axis="0 1 0" range="-2.0944 2.0944" limited="true" />
                <geom type="mesh" rgba="1 0.42 0 1" mesh="link_5" contype="1" conaffinity="2" />

                <body name="link_6" pos="0.08 0 0">
                  <joint name="joint_a6" pos="0 0 0" axis="-1 0 0" range="-6.10865 6.10865" limited="true" />
                  <geom type="mesh" rgba="0.3 0.3 0.3 1" mesh="link_6" contype="1" conaffinity="2" />

                  
                  <body name="suction_mount" pos="0.01 0 0">
  <joint name="cup_compliance" type="slide" axis="1 0 0" limited="true" range="-0.010 0" stiffness="800" damping="5" springref="0" />
  <body name="suction_pad">
    <geom name="cup_geom" type="cylinder" fromto="-0.005 0 0  0.005 0 0" size="0.03" rgba="0.15 0.15 0.18 1" margin="0.004" solref="0.02 1" solimp="0.9 0.95 0.001" contype="1" conaffinity="6" mass="0.05" />
    <site name="suction_tip_site" pos="0.006 0 0" euler="0 -90 0" size="0.005" rgba="1 0 0 0.5" />
    <camera name="cam_wrist" pos="-0.02 0 0.10" xyaxes="0 1 0 -0.342 0 -0.940" fovy="80" />
    <site name="cup_contact_site" pos="0.006 0 0" size="0.004" rgba="1 0.5 0 0" />
  </body>
</body></body>

              </body>
            </body>
          </body>
        </body>
      </body>

    </body>
  </worldbody>

  
  <actuator>
    
    <position name="act_a1" joint="joint_a1" kp="500" forcelimited="true" forcerange="-500 500" />
    <position name="act_a2" joint="joint_a2" kp="500" forcelimited="true" forcerange="-500 500" />
    <position name="act_a3" joint="joint_a3" kp="500" forcelimited="true" forcerange="-300 300" />
    <position name="act_a4" joint="joint_a4" kp="300" forcelimited="true" forcerange="-200 200" />
    <position name="act_a5" joint="joint_a5" kp="200" forcelimited="true" forcerange="-100 100" />
    <position name="act_a6" joint="joint_a6" kp="100" forcelimited="true" forcerange="-50  50" />
  <adhesion name="act_vacuum" body="suction_pad" ctrlrange="0 1" gain="40" /></actuator>

</mujoco>